Workbook

Sheet Navigation Tab
B2: Srno | C2: Sheet
B3: 1 | C3: Dashboard
B4: 2 | C4: Input
B5: 3 | C5: Assumptions
B6: 4 | C6: Revenue
B7: 5 | C7: Cost Sheet
B8: 6 | C8: Occupancy Analysis
B9: 7 | C9: Revenue Model
B10: 8 | C10: Profit & Loss
B11: 9 | C11: Cash Budget
B12: 10 | C12: Working Capital
B13: 11 | C13: Standard Costing
B14: 12 | C14: Flexible Budget
... B19: 17 | C19: Summary

Sheet Dashboard
R1: Navigation Tab
D2: 🏢 COWORKING SPACE — PANJAM, GOA DASHBOARD
M3: SCENARIO | P3: OCCUPANCY | S3: SELECT YEAR | V3: TOTAL SEATS | Y3: PRICE / SEAT | BT3: TABLE 1 — 5-YEAR P&L | CB3: REVENUE GROWTH TREND
M4: =Input!C6 -> Owned | P4: =TEXT(Input!C13,"0%") -> 80% | S4: 1 | V4: =Input!C10 -> 100 | Y4: =Input!C14 -> 7500 | BU4: Year 1 | BV4: Year 2 | BW4: Year 3 | BX4: Year 4 | BY4: Year 5 | CB4: Year | CC4: Year 1 | CD4: Year 2 | CE4: Year 3 | CF4: Year 4 | CG4: Year 5
M5: 📈 Performance Report — Owned Scenario | 80% Occupancy | Year 1 of 5 | BT5: Gross Revenue | BU5: ='P&L'!C8 -> 11196000 | BV5: ='P&L'!D8 -> 11755800 | BW5: ='P&L'!E8 -> 12343590 | BX5: ='P&L'!F8 -> 12960770 | BY5: ='P&L'!G8 -> 13608808 | CB5: Gross Revenue | CC5: ='P&L'!C8 -> 11196000 | CD5: ='P&L'!D8 -> 11755800 | CE5: ='P&L'!E8 -> 12343590 | CF5: ='P&L'!F8 -> 12960770 | CG5: ='P&L'!G8 -> 13608808
M6: ⚠️ RENT PREFERRED: Rent EBITDA ₹21L vs Owned ₹-209L | BEP price = ₹32,839 | Current price = ₹7,500 | BT6: Net Revenue | BU6: ='P&L'!C10 -> 10636200 | BV6: ='P&L'!D10 -> 11168010 | BW6: ='P&L'!E10 -> 11726410 | BX6: ='P&L'!F10 -> 12312731 | BY6: ='P&L'!G10 -> 12928368 | CB6: Net Revenue | CC6: ='P&L'!C10 -> 10636200 | CD6: ='P&L'!D10 -> 11168010 | CE6: ='P&L'!E10 -> 11726410 | CF6: ='P&L'!F10 -> 12312731 | CG6: ='P&L'!G10 -> 12928368
BT7: Total Cost | BU7: ='P&L'!C13+'P&L'!C24 -> 13596639 | BV7: ='P&L'!D13+'P&L'!D24 -> 13828239 | BW7: ='P&L'!E13+'P&L'!E24 -> 14071419 | BX7: ='P&L'!F13+'P&L'!F24 -> 14326758 | BY7: ='P&L'!G13+'P&L'!G24 -> 14594864
M8: KPIs | BT8: EBITDA | BU8: ='P&L'!C26 -> -2960439.4 | BV8: ='P&L'!D26 -> -2660229.4 | BW8: ='P&L'!E26 -> -2345008.9 | BX8: ='P&L'!F26 -> -2014027.3 | BY8: ='P&L'!G26 -> -1666496.7
O9: GROSS REVENUE | R9: EBITDA | U9: PAT (Net Profit) | X9: GROSS MARGIN % | BT9: PBT | BU9: ='P&L'!C41 -> -9919939.4 | BV9: ='P&L'!D41 -> -8675625.8 | BW9: ='P&L'!E41 -> -7463254.5 | BX9: ='P&L'!F41 -> -6269180.5 | BY9: ='P&L'!G41 -> -5083456.5 | CA9: Hot Desks | CB9: ='Revenue Model'!C7 -> 3240000 | CE9: Price per Seat per month | CF9: BEP Seats
O10: =INDEX('P&L'!C8:G8,1,S4) -> 11196000 | R10: =INDEX('P&L'!C26:G26,1,S4) -> -2960439.4 | U10: =INDEX('P&L'!C43:G43,1,S4) -> -9919939.4 | X10: =INDEX('P&L'!C15:G15,1,S4) -> 0.91876798 | BT10: PAT | BU10: ='P&L'!C43 -> -9919939.4 | BV10: ='P&L'!D43 -> -8675625.8 | BW10: ='P&L'!E43 -> -7463254.5 | BX10: ='P&L'!F43 -> -6269180.5 | BY10: ='P&L'!G43 -> -5083456.5 | CA10: Dedicated Desks | CB10: ='Revenue Model'!C8 -> 2484000 | CE10: ='Break Even'!B40 -> 5000 | CF10: ='Break Even'!C40 -> 259
O11: From P&L · Year I8 | R11: Before int & dep | U11: After tax · neg=loss | X11: GP / Net Revenue | CA11: Private Cabins | CB11: ='Revenue Model'!C9 -> 2016000 | CE11: ='Break Even'!B41 -> 6000 | CF11: ='Break Even'!C41 -> 209
BS12: TABLE 2 — CASH FLOW | CA12: Meeting Rooms | CB12: ='Revenue Model'!C10 -> 864000 | CE12: ='Break Even'!B42 -> 7500 | CF12: ='Break Even'!C42 -> 161
O13: NPV (7yr·WACC 10.5%) | R13: IRR | U13: BEP OCCUPANCY | X13: TOTAL CAPEX | BU13: Year 1 | BV13: Year 2 | BW13: Year 3 | BX13: Year 4 | BY13: Year 5 | CA13: Virtual Office Memberships | CB13: ='Revenue Model'!C11 -> 720000 | CE13: ='Break Even'!B43 -> 9000 | CF13: ='Break Even'!C43 -> 131
O14: ='Investment Appraisal'!C30 -> -1.1180426e+08 | R14: ='Investment Appraisal'!C31 -> Loss-making | U14: =TEXT('Break Even'!C28,"0%") -> 161% | X14: ='Cost sheet'!C15 -> 88950000 | BT14: Net Cash Flow | BU14: ='Cash Budget'!O22 -> -34242639 | BV14: ='Cash Budget'!C30 -> -2960439.4 | BW14: ='Cash Budget'!D30 -> -2660229.4 | BX14: ='Cash Budget'!E30 -> -2345008.9 | BY14: ='Cash Budget'!F30 -> -2014027.3 | CA14: Events & Workshops | CB14: ='Revenue Model'!C12 -> 720000 | CE14: ='Break Even'!B44 -> 10000 | CF14: ='Break Even'!C44 -> 117
O15: < 0 = destroys value | R15: vs WACC 12% hurdle | U15: >100% = unachievable | X15: Owned ₹23.9Cr·Rent ₹1.6Cr | BT15: Cumulative CF | BU15: =BU14 -> -34242639 | BV15: =BU15+BV14 -> -37203079 | BW15: =BV15+BW14 -> -39863308 | BX15: =BW15+BX14 -> -42208317 | BY15: =BX15+BY14 -> -44222344 | CA15: Workation Packages | CB15: ='Revenue Model'!C13 -> 1152000 | CE15: ='Break Even'!B45 -> 12000 | CF15: ='Break Even'!C45 -> 96
CE16: ='Break Even'!B46 -> 15000 | CF16: ='Break Even'!C46 -> 76
BT17: TABLE 3 — OCCUPANCY SENSITIVITY (Monthly EBITDA ₹) | CE17: ='Break Even'!B47 -> 18000 | CF17: ='Break Even'!C47 -> 63
BT18: Occ Level | BU18: 20% | BV18: 30% | BW18: 40% | BX18: 50% | BY18: 60% | BZ18: 70% | CA18: 80% | CB18: 90% | CC18: 100% | CE18: ='Break Even'!B48 -> 20000 | CF18: ='Break Even'!C48 -> 56
BT19: Monthly EBITDA | BU19: ='Break Even'!E53 -> -629803.28 | BV19: ='Break Even'!E54 -> -554428.28 | BW19: ='Break Even'!E55 -> -486553.28 | BX19: ='Break Even'!E56 -> -411178.28 | BY19: ='Break Even'!E57 -> -343303.28 | BZ19: ='Break Even'!E58 -> -267928.28 | CA19: ='Break Even'!E59 -> -200053.28 | CB19: ='Break Even'!E60 -> -124678.28 | CC19: ='Break Even'!E61 -> -56803.281 | CE19: ='Break Even'!B49 -> 25000 | CF19: ='Break Even'!C49 -> 45
BU20: Revenue Stream | BV20: Year 1
BT21: TABLE 4 — SCENARIO COMPARISON (₹ Crores) | CB21: Fixed vs Variable Cost Table
BT22: Scenario | BU22: Ann. EBITDA | BV22: Ann. PAT | BW22: Ann. Cost | CB22: Year | CC22: Year 1 | CD22: Year 2 | CE22: Year 3 | CF22: Year 4 | CG22: Year 5
BT23: Owned | BU23: ='P&L'!C26/10000000 -> -0.29604394 | BV23: ='P&L'!C43/10000000 -> -0.99199394 | BW23: ='Cost sheet'!C53*12/10000000 -> 1.3596639 | CB23: Fised cost | CC23: ='P&L'!C24 -> 12732639 | CD23: ='P&L'!D24 -> 12921039 | CE23: ='P&L'!E24 -> 13118859 | CF23: ='P&L'!F24 -> 13326570 | CG23: ='P&L'!G24 -> 13544667
BT24: Rent | BU24: ='Scenario '!D29/10000000 -> 0.21042 | BV24: ='Scenario '!D35/10000000 -> -0.04723 | BW24: ='Scenario '!D21*12/10000000 -> 0.8532 | CB24: Variable Cost | CC24: ='P&L'!C13 -> 864000 | CD24: ='P&L'!D13 -> 907200 | CE24: ='P&L'!E13 -> 952560 | CF24: ='P&L'!F13 -> 1000188 | CG24: ='P&L'!G13 -> 1050197.4
BT26: TABLE 5 — ANNUAL COST STRUCTURE (₹) | CB26: Net Cash Flow Trend Chart
BT27: Category | BU27: EMI/Rent | BV27: Salaries | BW27: Utilities | BX27: Mktg & Admin | BY27: Variable | CB27: Year | CC27: Yr 0 | CD27: Yr 1 | CE27: Yr 2 | CF27: Yr 3 | CG27: Yr 4 | CH27: Yr 5
BT28: Annual Cost | BU28: ='Cost sheet'!C20*12 -> 8964639.4 | BV28: =('Cost sheet'!C21+'Cost sheet'!C22+'Cost sheet'!C23+'Cost sheet'!C24+'Cost sheet'!C25+'Cost sheet'!C26)*12 -> 2388000 | BW28: =('Cost sheet'!C27+'Cost sheet'!C28+'Cost sheet'!C29)*12 -> 936000 | BX28: =('Cost sheet'!C30+'Cost sheet'!C31+'Cost sheet'!C32+'Cost sheet'!C33)*12 -> 444000 | BY28: ='Cost sheet'!C49*'Cost sheet'!C43*12 -> 864000 | CB28: Net Cash Flow | CC28: ='Investment Appraisal'!C19 -> -88950000 | CD28: ='Investment Appraisal'!D19 -> -8297439.4 | CE28: ='Investment Appraisal'!E19 -> -7234800.8 | CF28: ='Investment Appraisal'!F19 -> -6157151.7 | CG28: ='Investment Appraisal'!G19 -> -5063741.6 | CH28: ='Investment Appraisal'!H19 -> -3953782.5

Sheet Input
B1: Navigation Tab
B2: 🏢 COWORKING SPACE FINANCIAL MODEL — PANAJI, GOA
B3: CONTROL PANEL | Input Sheet | All model outputs update automatically
B5: SCENARIO SELECTION
B6: Property Scenario | C6: Owned
B8: SPACE PARAMETERS
B9: Parameter | C9: Value | D9: Unit | E9: Notes
B10: Total Seats | C10: 100 | D10: seats | E10: Fixed at 100
B11: Area per Seat | C11: 50 | D11: sq ft | E11: Industry standard
B12: Total Area | C12: =C10*C11 -> 5000 | D12: sq ft | E12: Auto-calculated
B13: Occupancy Rate | C13: 0.8 | D13: % | E13: Select: 0.4 / 0.6 / 0.8 (= 40% / 60% / 80%)
B14: Price per Seat (Hot Desk) | C14: 7500 | D14: ₹/month | E14: Panjim market: ₹5k–₹10k
B16: FINANCIAL & MACRO PARAMETERS
B17: Parameter | C17: Value | D17: Unit | E17: Notes
B18: Revenue Inflation Rate | C18: 0.05 | D18: % | E18: YoY price increase
B19: Cost Escalation Rate | C19: 0.05 | D19: % | E19: YoY cost increase
B20: WACC (Discount Rate) | C20: =WACC!C13 -> 0.105 | D20: % | E20: Weighted Avg Cost of Capital
B21: Corporate Tax Rate | C21: 0.25 | D21: % | E21: India standard rate
B22: Loan Interest Rate | C22: 0.1 | D22: % | E22: Term loan rate (if financed)
B23: Loan Tenure | C23: 7 | D23: years | E23: Standard commercial loan
B24: Depreciation Rate | C24: 0.2 | D24: % | E24: WDV method for furniture/fit-out
B25: Advance Payment Period | C25: 2 | D25: months | E25: Months of advance subscription collected upfront
B27: MARKET BENCHMARKS (PANJIM, GOA)
B28: Category | C28: Low | D28: High | E28: Source
B29: Hot Desk Price | C29: 5000 | D29: 10000 | E29: Qdesq / GoFloaters
B30: Premium Desk Price | C30: 8000 | D30: 12000 | E30: Qdesq
B31: Daily Desk Rate | C31: 400 | D31: 600 | E31: GoFloaters
B32: Office Rent per sq ft | C32: 50 | D32: 80 | E32: MagicBricks
B33: Fit-out Cost per sq ft | C33: 1500 | D33: 2000 | E33: Industry benchmark
B34: Furniture per Seat | C34: 20000 | D34: 30000 | E34: Industry benchmark

Sheet Assumptions
B1: Navigation Tab
B2: ASSUMPTIONS SHEET — OWNED vs. RENT SCENARIO COMPARISON
B3: Selected Value column is driven by Input!C6 scenario. All other sheets reference Column E only.
B5: ASSUMPTIONS TABLE
B6: Variable / Parameter | C6: OWNED Scenario | D6: RENT Scenario | E6: SELECTED VALUE | F6: Notes
B7: A. PROPERTY & SPACE COSTS
B8: Rent per sq ft (₹/month) | C8: 0 | D8: 65 | E8: =IF(Input!C6="Owned",C8,D8) -> 0 | F8: 0 for owned; avg Panjim rate
B9: Property Purchase Cost (₹/sq ft) | C9: 15000 | D9: 0 | E9: =IF(Input!C6="Owned",C9,D9) -> 15000 | F9: Market value Panjim CRE
B10: Security Deposit (months of rent) | C10: 0 | D10: 6 | E10: =IF(Input!C6="Owned",C10,D10) -> 0 | F10: Typically 6 months in Goa
B11: CAPEX — Interiors (₹/sq ft) | C11: 1750 | D11: 1750 | E11: =IF(Input!C6="Owned",C11,D11) -> 1750 | F11: ₹1500–₹2000 range; mid-point
B12: CAPEX — Furniture per seat (₹) | C12: 25000 | D12: 25000 | E12: =IF(Input!C6="Owned",C12,D12) -> 25000 | F12: ₹20k–₹30k; mid-point
B13: CAPEX — IT & Networking (₹ lakh) | C13: 7.5 | D13: 7.5 | E13: =IF(Input!C6="Owned",C13,D13) -> 7.5 | F13: Servers, switches, WiFi6
B14: CAPEX — Electrical & AC (₹ lakh) | C14: 12.5 | D14: 12.5 | E14: =IF(Input!C6="Owned",C14,D14) -> 12.5 | F14: VRF + DB panels
B15: CAPEX — Branding & Signage (₹ lakh) | C15: 4 | D15: 4 | E15: =IF(Input!C6="Owned",C15,D15) -> 4 | F15: Interior + exterior brand
B16: CAPEX — Misc / Contingency (₹ lakh) | C16: 3 | D16: 3 | E16: =IF(Input!C6="Owned",C16,D16) -> 3 | F16: 5–10% buffer
B18: B. DEPRECIATION & FINANCING
B19: Depreciation Rate — Fit-out (%) | C19: 0.1 | D19: 0.1 | E19: =IF(Input!C6="Owned",C19,D19) -> 0.1 | F19: SLM over 10 years
B20: Depreciation Rate — Furniture (%) | C20: 0.2 | D20: 0.2 | E20: =IF(Input!C6="Owned",C20,D20) -> 0.2 | F20: WDV method
B21: Depreciation Rate — IT (%) | C21: 0.33 | D21: 0.33 | E21: =IF(Input!C6="Owned",C21,D21) -> 0.33 | F21: 3-year life
B22: Loan-to-Cost Ratio (%) | C22: 0.6 | D22: 0.6 | E22: =IF(Input!C6="Owned",C22,D22) -> 0.6 | F22: 60% debt financing assumed
B23: Cost Escalation Rate | C23: 0.05 | D23: 0.05 | E23: =Input!C19 -> 0.05 | F23: Links to Input!C19 — applied to all OpEx year-on-year
B25: C. STAFFING (MONTHLY SALARIES)
B26: Centre Manager (1) | C26: 50000 | D26: 50000 | E26: =IF(Input!C6="Owned",C26,D26) -> 50000 | F26: Panjim market
B27: Front Desk / Community (2) | C27: 25000 | D27: 25000 | E27: =IF(Input!C6="Owned",C27,D27) -> 25000 | F27: Per person
B28: IT Support (1 part-time) | C28: 15000 | D28: 15000 | E28: =IF(Input!C6="Owned",C28,D28) -> 15000 | F28: Part-time
B29: Housekeeping & Security (3) | C29: 14000 | D29: 14000 | E29: =IF(Input!C6="Owned",C29,D29) -> 14000 | F29: Per person
B30: Marketing / Social (1) | C30: 20000 | D30: 20000 | E30: =IF(Input!C6="Owned",C30,D30) -> 20000 | F30: In-house
B31: Accounts / Admin (1) | C31: 22000 | D31: 22000 | E31: =IF(Input!C6="Owned",C31,D31) -> 22000 | F31: Part-time
B33: D. UTILITIES & FIXED MONTHLY COSTS
B34: Internet (leased line, Gbps) | C34: 18000 | D34: 18000 | E34: =IF(Input!C6="Owned",C34,D34) -> 18000 | F34: 1 Gbps leased line Goa
B35: Electricity — Base (₹/month) | C35: 45000 | D35: 45000 | E35: =IF(Input!C6="Owned",C35,D35) -> 45000 | F35: AC + common area
B36: Maintenance & Repairs | C36: 15000 | D36: 15000 | E36: =IF(Input!C6="Owned",C36,D36) -> 15000 | F36: Monthly upkeep
B37: Marketing & Digital Ads | C37: 20000 | D37: 20000 | E37: =IF(Input!C6="Owned",C37,D37) -> 20000 | F37: Google + Instagram
B38: Admin & Office Expenses | C38: 8000 | D38: 8000 | E38: =IF(Input!C6="Owned",C38,D38) -> 8000 | F38: Consumables, printing
B39: Insurance (monthly equiv.) | C39: 6000 | D39: 6000 | E39: =IF(Input!C6="Owned",C39,D39) -> 6000 | F39: CRE + asset insurance
B40: Telephone / Misc Utilities | C40: 3000 | D40: 3000 | E40: =IF(Input!C6="Owned",C40,D40) -> 3000 | F40: Misc utilities
B42: E. VARIABLE COSTS (PER OCCUPIED SEAT / MONTH)
B43: Electricity per user (₹/seat) | C43: 350 | D43: 350 | E43: =IF(Input!C6="Owned",C43,D43) -> 350 | F43: Usage-based allocation
B44: Pantry / Beverages (₹/seat) | C44: 200 | D44: 200 | E44: =IF(Input!C6="Owned",C44,D44) -> 200 | F44: Tea, coffee, snacks
B45: Cleaning per seat (₹/seat) | C45: 150 | D45: 150 | E45: =IF(Input!C6="Owned",C45,D45) -> 150 | F45: Incremental cleaning
...

Sheet Revenue
B1: Navigation Tab
B2: BUSINESS MODEL & REVENUE STREAMS — MONTHLY PROJECTION
B3: All values linked to Input Sheet. Change Occupancy or Price in Input to update all revenue figures.
B5: CAPACITY & OCCUPANCY SUMMARY
B6: Total Installed Seats | C6: =Input!C10 -> 100 | D6: seats
B7: Area per Seat | C7: =Input!C11 -> 50 | D7: sq ft
B8: Total Leasable Area | C8: =Input!C12 -> 5000 | D8: sq ft
B9: Occupancy Rate | C9: =Input!C13 -> 0.8 | D9: %
B10: Occupied Seats (monthly) | C10: =Input!C10*Input!C13 -> 80 | D10: seats
B12: MONTHLY REVENUE STREAMS
B13: Revenue Stream | C13: Units / Qty | D13: Price (₹) | E13: Occupancy Adj. | F13: Monthly Revenue (₹) | G13: % of Total | H13: Notes
B14: Hot Desks | C14: =ROUND(Input!C10*Input!C13*0.45,0) -> 36 | D14: =Input!C14 -> 7500 | E14: 1 | F14: =C14*D14*E14 -> 270000 | G14: =IF(F21=0,"-",F14/F21) -> 0.28938907 | H14: 45% of occupied seats on hot-desk plan
B15: Dedicated Desks | C15: =ROUND(Input!C10*Input!C13*0.3,0) -> 24 | D15: =Input!C14*1.15 -> 8625 | E15: 1 | F15: =C15*D15*E15 -> 207000 | G15: =IF(F21=0,"-",F15/F21) -> 0.22186495 | H15: 30% seats; 15% premium over hot-desk
B16: Private Cabins (5 cabins × 4 seats) | C16: =ROUND(Input!C10*Input!C13*0.2,0) -> 16 | D16: =Input!C14*1.4 -> 10500 | E16: 1 | F16: =C16*D16*E16 -> 168000 | G16: =IF(F21=0,"-",F16/F21) -> 0.18006431 | H16: Private cabin premium 40%
B17: Meeting Rooms (3 rooms) | C17: 60 | D17: 1200 | E17: 1 | F17: =C17*D17*E17 -> 72000 | G17: =IF(F21=0,"-",F17/F21) -> 0.077170418 | H17: 3 rooms × 20 bookings/month — update units/price in this row directly
B18: Virtual Office Memberships | C18: 30 | D18: 2000 | E18: 1 | F18: =C18*D18*E18 -> 60000 | G18: =IF(F21=0,"-",F18/F21) -> 0.064308682 | H18: 30 virtual members @ ₹2k/month
B19: Events & Workshops | C19: 4 | D19: 15000 | E19: 1 | F19: =C19*D19*E19 -> 60000 | G19: =IF(F21=0,"-",F19/F21) -> 0.064308682 | H19: 4 events/month avg
B20: Workation Packages (weekly) | C20: 8 | D20: 12000 | E20: 1 | F20: =C20*D20*E20 -> 96000 | G20: =IF(F21=0,"-",F20/F21) -> 0.10289389 | H20: 8 workation bookings/month
B21: TOTAL MONTHLY REVENUE | F21: =SUM(F14:F20) -> 933000 | G21: =SUM(G14:G20) -> 1
B23: ANNUAL REVENUE INDICATORS
B24: Monthly Revenue | C24: =F21 -> 933000
B25: Annual Revenue (Yr 1) | C25: =F21*12 -> 11196000
B26: Revenue per Occupied Seat | C26: =IF(C10=0,0,F21/C10) -> 11662.5
B27: Revenue per Total Seat | C27: =IF(Input!C10=0,0,F21/Input!C10) -> 9330
B28: Annual Revenue (Yr 2, +5%) | C28: =F21*12*(1+Input!C18) -> 11755800
B29: Annual Revenue (Yr 3, +5%) | C29: =F21*12*(1+Input!C18)^2 -> 12343590
B30: Annual Revenue (Yr 4, +5%) | C30: =F21*12*(1+Input!C18)^3 -> 12960770
B31: Annual Revenue (Yr 5, +5%) | C31: =F21*12*(1+Input!C18)^4 -> 13608808
B32: 5-Year Revenue CAGR | C32: =IFERROR((C31/C25)^(1/4)-1,0) -> 0.05
B33: 5-Year Cumulative Revenue | C33: =C25+C28+C29+C30+C31 -> 61864967

Sheet Cost sheet
B1: Navigation Tab
B2: COST SHEET — CAPEX, FIXED & VARIABLE COSTS (DYNAMIC)
B3: CAPEX & operating costs update automatically when Scenario / Seats / Occupancy change in the Input sheet.
B5: PART A — CAPITAL EXPENDITURE (CAPEX)
B6: CAPEX Component | C6: Value (₹) | D6: Notes | E6: Scenario
B7: Interior Fit-out | C7: =Input!C12*Assumptions!E11 -> 8750000 | D7: Total area × ₹1,750/sq ft | E7: =IF(Input!C6="Owned","Owned","Rent") -> Owned
B8: Furniture & Workstations | C8: =Input!C10*Assumptions!E12 -> 2500000 | D8: Per seat × 100 seats | E8: =IF(Input!C6="Owned","Owned","Rent") -> Owned
B9: IT & Networking Setup | C9: =Assumptions!E13*100000 -> 750000 | D9: Servers, APs, switches | E9: =IF(Input!C6="Owned","Owned","Rent") -> Owned
B10: Electrical, AC & MEP | C10: =Assumptions!E14*100000 -> 1250000 | D10: VRF AC + distribution | E10: =IF(Input!C6="Owned","Owned","Rent") -> Owned
B11: Branding & Signage | C11: =Assumptions!E15*100000 -> 400000 | D11: Interior + exterior | E11: =IF(Input!C6="Owned","Owned","Rent") -> Owned
B12: Misc / Contingency | C12: =Assumptions!E16*100000 -> 300000 | D12: ~5% buffer | E12: =IF(Input!C6="Owned","Owned","Rent") -> Owned
B13: Security Deposit (Rent only) | C13: =IF(Input!C6="Rent",Input!C12*Assumptions!E8*Assumptions!E10,0) -> 0 | D13: Only applicable in Rent scenario | E13: =IF(Input!C6="Owned","Owned","Rent") -> Owned
B14: Property Purchase (Owned only) | C14: =IF(Input!C6="Owned",Input!C12*Assumptions!E9,0) -> 75000000 | D14: Only applicable in Owned scenario | E14: =IF(Input!C6="Owned","Owned","Rent") -> Owned
B15: TOTAL CAPEX | C15: =SUM(C7:C14) -> 88950000
B16: CAPEX per Occupied Seat | C16: =IF(Input!C10=0,0,C15/Input!C10) -> 889500 | D16: Total CAPEX / total seats
B18: PART B — FIXED MONTHLY OPERATING COSTS
B19: Cost Item | C19: Monthly Cost (₹) | D19: Notes
B20: Rent / Property Cost | C20: =IF(Input!C6="Rent",Input!C12*Assumptions!E8,IFERROR(Assumptions!E9*Input!C12*Assumptions!E22*(Input!C22/12)*(1+Input!C22/12)^(Input!C23*12)/((1+Input!C22/12)^(Input!C23*12)-1),0)) -> 747053.28 | D20: Rent: area × ₹65/sqft | Owned: EMI on 60% LTV
B21: Salaries — Manager (1) | C21: =Assumptions!E26 -> 50000 | D21: Centre manager
B22: Salaries — Front Desk (2) | C22: =Assumptions!E27*2 -> 50000 | D22: 2 community hosts
B23: Salaries — IT Support | C23: =Assumptions!E28 -> 15000 | D23: Part-time IT
B24: Salaries — Housekeeping & Security (3) | C24: =Assumptions!E29*3 -> 42000 | D24: 3 staff
B25: Salaries — Marketing | C25: =Assumptions!E30 -> 20000 | D25: In-house
B26: Salaries — Admin/Accounts | C26: =Assumptions!E31 -> 22000 | D26: Part-time
B27: Internet (Leased Line) | C27: =Assumptions!E34 -> 18000 | D27: 1 Gbps
B28: Electricity — Base Load | C28: =Assumptions!E35 -> 45000 | D28: Common area + AC base
B29: Maintenance & Upkeep | C29: =Assumptions!E36 -> 15000 | D29: Monthly repairs
B30: Marketing & Digital | C30: =Assumptions!E37 -> 20000 | D30: Ads + SEO
B31: Admin & Office Expenses | C31: =Assumptions!E38 -> 8000 | D31: Stationery, printing
B32: Insurance | C32: =Assumptions!E39 -> 6000 | D32: CRE + asset
B33: Misc Utilities | C33: =Assumptions!E40 -> 3000 | D33: Telephone, water, misc
B34: TOTAL FIXED MONTHLY COST | C34: =SUM(C20:C33) -> 1061053.3
B36: PART C — VARIABLE COSTS (PER OCCUPIED SEAT)
B37: Variable Cost Item | C37: ₹ per seat/month | D37: Notes
B38: Electricity (usage-based) | C38: =Assumptions!E43 -> 350 | D38: Per active seat
B39: Pantry & Beverages | C39: =Assumptions!E44 -> 200 | D39: Tea, coffee, snacks
B40: Incremental Cleaning | C40: =Assumptions!E45 -> 150 | D40: Cleaning per user
B41: Internet (bandwidth alloc) | C41: =Assumptions!E46 -> 120 | D41: Per user bandwidth
B42: Stationery & Consumables | C42: =Assumptions!E47 -> 80 | D42: Per active user
B43: TOTAL VARIABLE COST per Seat | C43: =SUM(C38:C42) -> 900
...

Sheet Occupancy
B1: Navigation Tab
B2: OCCUPANCY & CAPACITY ANALYSIS
B3: Scenario matrix for 40% / 60% / 80% occupancy — all values linked to Input & Costs sheets
B5: SECTION A — CAPACITY SUMMARY
B6: Parameter | C6: Value | D6: Unit
B7: Total Installed Seats | C7: =Input!C10 -> 100 | D7: seats
B8: Total Leasable Area | C8: =Input!C12 -> 5000 | D8: sq ft
B9: Area per Seat | C9: =Input!C12/Input!C10 -> 50 | D9: sq ft
B10: Current Occupancy Setting | C10: =Input!C13 -> 0.8 | D10: %
B11: Currently Occupied Seats | C11: =Input!C10*Input!C13 -> 80 | D11: seats
B12: Currently Unoccupied Seats | C12: =Input!C10-Input!C10*Input!C13 -> 20 | D12: seats
B13: Revenue per Occupied Seat/mo | C13: =IFERROR(Revenue!F21/(Input!C10*Input!C13),0) -> 11662.5 | D13: ₹/seat
B14: Cost per Occupied Seat/mo | C14: =IFERROR('Cost sheet'!C53/(Input!C10*Input!C13),0) -> 14163.166 | D14: ₹/seat
B16: SECTION B — OCCUPANCY SCENARIO MATRIX
B17: Metric | C17: 40% Occupancy | D17: 60% Occupancy | E17: 80% Occupancy | F17: Active Scenario
B18: Occupied Seats | C18: =ROUND(Input!C10*0.4,0) -> 40 | D18: =ROUND(Input!C10*0.6,0) -> 60 | E18: =ROUND(Input!C10*0.8,0) -> 80 | F18: =IF(Input!C13=0.4,C18,IF(Input!C13=0.6,D18,E18)) -> 80
B19: Unoccupied Seats | C19: =Input!C10-C18 -> 60 | D19: =Input!C10-D18 -> 40 | E19: =Input!C10-E18 -> 20 | F19: =IF(Input!C13=0.4,C19,IF(Input!C13=0.6,D19,E19)) -> 20
B20: Utilisation Rate | C20: =40% -> 0.4 | D20: =60% -> 0.6 | E20: =80% -> 0.8 | F20: =IF(Input!C13=0.4,C20,IF(Input!C13=0.6,D20,E20)) -> 0.8
B21: Hot Desk Monthly Revenue | C21: =ROUND(Input!C10*0.4*0.45,0)*Input!C14 -> 135000 | D21: =ROUND(Input!C10*0.6*0.45,0)*Input!C14 -> 202500 | E21: =ROUND(Input!C10*0.8*0.45,0)*Input!C14 -> 270000 | F21: =IF(Input!C13=0.4,C21,IF(Input!C13=0.6,D21,E21)) -> 270000
B22: Dedicated Desk Monthly Revenue | C22: =ROUND(Input!C10*0.4*0.3,0)*Input!C14*1.15 -> 103500 | D22: =ROUND(Input!C10*0.6*0.3,0)*Input!C14*1.15 -> 155250 | E22: =ROUND(Input!C10*0.8*0.3,0)*Input!C14*1.15 -> 207000 | F22: =IF(Input!C13=0.4,C22,IF(Input!C13=0.6,D22,E22)) -> 207000
B23: Private Cabin Monthly Revenue | C23: =ROUND(Input!C10*0.4*0.2,0)*Input!C14*1.4 -> 84000 | D23: =ROUND(Input!C10*0.6*0.2,0)*Input!C14*1.4 -> 126000 | E23: =ROUND(Input!C10*0.8*0.2,0)*Input!C14*1.4 -> 168000 | F23: =IF(Input!C13=0.4,C23,IF(Input!C13=0.6,D23,E23)) -> 168000
B24: Other Revenue (Mtg Rooms + VO + Events + Workation) | C24: =Revenue!F17+Revenue!F18+Revenue!F19+Revenue!F20 -> 288000 | D24: =Revenue!F17+Revenue!F18+Revenue!F19+Revenue!F20 -> 288000 | E24: =Revenue!F17+Revenue!F18+Revenue!F19+Revenue!F20 -> 288000 | F24: =IF(Input!C13=0.4,C24,IF(Input!C13=0.6,D24,E24)) -> 288000
B25: TOTAL MONTHLY REVENUE | C25: =C21+C22+C23+C24 -> 610500 | D25: =D21+D22+D23+D24 -> 771750 | E25: =E21+E22+E23+E24 -> 933000 | F25: =IF(Input!C13=0.4,C25,IF(Input!C13=0.6,D25,E25)) -> 933000
B26: Total Variable Cost | C26: ='Cost sheet'!C43*C18 -> 36000 | D26: ='Cost sheet'!C43*D18 -> 54000 | E26: ='Cost sheet'!C43*E18 -> 72000 | F26: =IF(Input!C13=0.4,C26,IF(Input!C13=0.6,D26,E26)) -> 72000
B27: Total Fixed Cost | C27: ='Cost sheet'!C34 -> 1061053.3 | D27: ='Cost sheet'!C34 -> 1061053.3 | E27: ='Cost sheet'!C34 -> 1061053.3 | F27: =IF(Input!C13=0.4,C27,IF(Input!C13=0.6,D27,E27)) -> 1061053.3
B28: TOTAL MONTHLY COST | C28: =C26+C27 -> 1097053.3 | D28: =D26+D27 -> 1115053.3 | E28: =E26+E27 -> 1133053.3 | F28: =IF(Input!C13=0.4,C28,IF(Input!C13=0.6,D28,E28)) -> 1133053.3
B29: Monthly Profit / (Loss) | C29: =C25-C28 -> -486553.28 | D29: =D25-D28 -> -343303.28 | E29: =E25-E28 -> -200053.28 | F29: =IF(Input!C13=0.4,C29,IF(Input!C13=0.6,D29,E29)) -> -200053.28
B30: Operating Margin % | C30: =IFERROR(C29/C25,0) -> -0.79697507 | D30: =IFERROR(D29/D25,0) -> -0.44483742 | E30: =IFERROR(E29/E25,0) -> -0.21441938 | F30: =IF(Input!C13=0.4,C30,IF(Input!C13=0.6,D30,E30)) -> -0.21441938
B31: Break-even Contribution (Revenue - Variable Cost) | C31: =C25-C26 -> 574500 | D31: =D25-D26 -> 717750 | E31: =E25-E26 -> 861000 | F31: =IF(Input!C13=0.4,C31,IF(Input!C13=0.6,D31,E31)) -> 861000
B33: SECTION C — 5-YEAR ANNUAL REVENUE TREND (WITH INFLATION)
B34: Year | C34: 40% Occupancy (₹) | D34: 60% Occupancy (₹) | E34: 80% Occupancy (₹) | F34: Active Scenario (₹)
B35: Year 1 | C35: =C25*12 -> 7326000 | D35: =D25*12 -> 9261000 | E35: =E25*12 -> 11196000 | F35: =IF(Input!C13=0.4,C35,IF(Input!C13=0.6,D35,E35)) -> 11196000
B36: Year 2 | C36: =C25*12*(1+Input!C18)^1 -> 7692300 | D36: =D25*12*(1+Input!C18)^1 -> 9724050 | E36: =E25*12*(1+Input!C18)^1 -> 11755800 | F36: =IF(Input!C13=0.4,C36,IF(Input!C13=0.6,D36,E36)) -> 11755800
B37: Year 3 | C37: =C25*12*(1+Input!C18)^2 -> 8076915 | D37: =D25*12*(1+Input!C18)^2 -> 10210252 | E37: =E25*12*(1+Input!C18)^2 -> 12343590 | F37: =IF(Input!C13=0.4,C37,IF(Input!C13=0.6,D37,E37)) -> 12343590
B38: Year 4 | C38: =C25*12*(1+Input!C18)^3 -> 8480760.8 | D38: =D25*12*(1+Input!C18)^3 -> 10720765 | E38: =E25*12*(1+Input!C18)^3 -> 12960770 | F38: =IF(Input!C13=0.4,C38,IF(Input!C13=0.6,D38,E38)) -> 12960770
B39: Year 5 | C39: =C25*12*(1+Input!C18)^4 -> 8904798.8 | D39: =D25*12*(1+Input!C18)^4 -> 11256803 | E39: =E25*12*(1+Input!C18)^4 -> 13608808 | F39: =IF(Input!C13=0.4,C39,IF(Input!C13=0.6,D39,E39)) -> 13608808
B42: SECTION D — REVENUE & COST PER SEAT ANALYSIS
B43: KPI | C43: Value | D43: Unit | E43: Comment
B44: Revenue per Installed Seat / month | C44: =IFERROR(Revenue!F21/Input!C10,0) -> 9330 | D44: ₹/seat | E44: Based on current occupancy
B45: Revenue per Occupied Seat / month | C45: =IFERROR(Revenue!F21/(Input!C10*Input!C13),0) -> 11662.5 | D45: ₹/seat | E45: Active members only
...

Sheet Revenue Model
B1: Navigation Tab
B2: REVENUE MODEL — 5-YEAR ANNUAL PROJECTION
B3: Year 1 linked to Revenue sheet. Years 2–5 compound Input!C18 inflation annually. No hardcoding.
B5: PART 1 — ANNUAL REVENUE BY STREAM (₹)
B6: Revenue Stream | C6: Year 1 | D6: Year 2 | E6: Year 3 | F6: Year 4 | G6: Year 5 | H6: 5-Year Total
B7: Hot Desks | C7: =Revenue!F14*12 -> 3240000 | D7: =C7*(1+Input!C18) -> 3402000 | E7: =D7*(1+Input!C18) -> 3572100 | F7: =E7*(1+Input!C18) -> 3750705 | G7: =F7*(1+Input!C18) -> 3938240.2 | H7: =SUM(C7:G7) -> 17903045
B8: Dedicated Desks | C8: =Revenue!F15*12 -> 2484000 | D8: =C8*(1+Input!C18) -> 2608200 | E8: =D8*(1+Input!C18) -> 2738610 | F8: =E8*(1+Input!C18) -> 2875540.5 | G8: =F8*(1+Input!C18) -> 3019317.5 | H8: =SUM(C8:G8) -> 13725668
B9: Private Cabins | C9: =Revenue!F16*12 -> 2016000 | D9: =C9*(1+Input!C18) -> 2116800 | E9: =D9*(1+Input!C18) -> 2222640 | F9: =E9*(1+Input!C18) -> 2333772 | G9: =F9*(1+Input!C18) -> 2450460.6 | H9: =SUM(C9:G9) -> 11139673
B10: Meeting Rooms | C10: =Revenue!F17*12 -> 864000 | D10: =C10*(1+Input!C18) -> 907200 | E10: =D10*(1+Input!C18) -> 952560 | F10: =E10*(1+Input!C18) -> 1000188 | G10: =F10*(1+Input!C18) -> 1050197.4 | H10: =SUM(C10:G10) -> 4774145.4
B11: Virtual Office Memberships | C11: =Revenue!F18*12 -> 720000 | D11: =C11*(1+Input!C18) -> 756000 | E11: =D11*(1+Input!C18) -> 793800 | F11: =E11*(1+Input!C18) -> 833490 | G11: =F11*(1+Input!C18) -> 875164.5 | H11: =SUM(C11:G11) -> 3978454.5
B12: Events & Workshops | C12: =Revenue!F19*12 -> 720000 | D12: =C12*(1+Input!C18) -> 756000 | E12: =D12*(1+Input!C18) -> 793800 | F12: =E12*(1+Input!C18) -> 833490 | G12: =F12*(1+Input!C18) -> 875164.5 | H12: =SUM(C12:G12) -> 3978454.5
B13: Workation Packages | C13: =Revenue!F20*12 -> 1152000 | D13: =C13*(1+Input!C18) -> 1209600 | E13: =D13*(1+Input!C18) -> 1270080 | F13: =E13*(1+Input!C18) -> 1333584 | G13: =F13*(1+Input!C18) -> 1400263.2 | H13: =SUM(C13:G13) -> 6365527.2
B14: TOTAL ANNUAL REVENUE | C14: =SUM(C7:C13) -> 11196000 | D14: =SUM(D7:D13) -> 11755800 | E14: =SUM(E7:E13) -> 12343590 | F14: =SUM(F7:F13) -> 12960770 | G14: =SUM(G7:G13) -> 13608808 | H14: =SUM(H7:H13) -> 61864967
B15: Revenue Growth YoY % | C15: - | D15: =IFERROR((D14-C14)/C14,0) -> 0.05 | E15: =IFERROR((E14-D14)/D14,0) -> 0.05 | F15: =IFERROR((F14-E14)/E14,0) -> 0.05 | G15: =IFERROR((G14-F14)/F14,0) -> 0.05 | H15: -
B17: PART 2 — MONTHLY REVENUE MIX (YEAR 1 BASE)
B18: Stream | C18: Monthly (₹) | D18: Annual (₹) | E18: % of Total Rev | F18: Unit Price (₹) | G18: Units / Month
B19: Hot Desks | C19: =Revenue!F14 -> 270000 | D19: =Revenue!F14*12 -> 3240000 | E19: =IFERROR(Revenue!F14/Revenue!F21,0) -> 0.28938907 | F19: =Revenue!D14 -> 7500 | G19: =Revenue!C14 -> 36
B20: Dedicated Desks | C20: =Revenue!F15 -> 207000 | D20: =Revenue!F15*12 -> 2484000 | E20: =IFERROR(Revenue!F15/Revenue!F21,0) -> 0.22186495 | F20: =Revenue!D15 -> 8625 | G20: =Revenue!C15 -> 24
B21: Private Cabins | C21: =Revenue!F16 -> 168000 | D21: =Revenue!F16*12 -> 2016000 | E21: =IFERROR(Revenue!F16/Revenue!F21,0) -> 0.18006431 | F21: =Revenue!D16 -> 10500 | G21: =Revenue!C16 -> 16
B22: Meeting Rooms | C22: =Revenue!F17 -> 72000 | D22: =Revenue!F17*12 -> 864000 | E22: =IFERROR(Revenue!F17/Revenue!F21,0) -> 0.077170418 | F22: =Revenue!D17 -> 1200 | G22: =Revenue!C17 -> 60
B23: Virtual Office Memberships | C23: =Revenue!F18 -> 60000 | D23: =Revenue!F18*12 -> 720000 | E23: =IFERROR(Revenue!F18/Revenue!F21,0) -> 0.064308682 | F23: =Revenue!D18 -> 2000 | G23: =Revenue!C18 -> 30
B24: Events & Workshops | C24: =Revenue!F19 -> 60000 | D24: =Revenue!F19*12 -> 720000 | E24: =IFERROR(Revenue!F19/Revenue!F21,0) -> 0.064308682 | F24: =Revenue!D19 -> 15000 | G24: =Revenue!C19 -> 4
B25: Workation Packages | C25: =Revenue!F20 -> 96000 | D25: =Revenue!F20*12 -> 1152000 | E25: =IFERROR(Revenue!F20/Revenue!F21,0) -> 0.10289389 | F25: =Revenue!D20 -> 12000 | G25: =Revenue!C20 -> 8
B26: TOTAL | C26: =Revenue!F21 -> 933000 | D26: =Revenue!F21*12 -> 11196000 | E26: =SUM(E19:E25) -> 1 | F26: - | G26: -
B28: PART 3 — 5-YEAR REVENUE KPIs
B29: KPI | C29: Value | D29: Unit
B30: Year 1 Annual Revenue | C30: =C14 -> 11196000 | D30: ₹
B31: Year 5 Annual Revenue | C31: =G14 -> 13608808 | D31: ₹
B32: 5-Year Cumulative Revenue | C32: =H14 -> 61864967 | D32: ₹
B33: Revenue CAGR (4-year) | C33: =IFERROR((G14/C14)^(1/4)-1,0) -> 0.05 | D33: %
B34: Average Annual Revenue | C34: =H14/5 -> 12372993 | D34: ₹
B35: Monthly Revenue (current base) | C35: =Revenue!F21 -> 933000 | D35: ₹
B36: Revenue per Seat / year | C36: =IFERROR(Revenue!F21*12/Input!C10,0) -> 111960 | D36: ₹
B37: Revenue per Occupied Seat / yr | C37: =IFERROR(Revenue!F21*12/(Input!C10*Input!C13),0) -> 139950 | D37: ₹
B38: Revenue Inflation Rate (input) | C38: =Input!C18 -> 0.05 | D38: %

Sheet P&L
B1: Navigation Tab
B2: PROFIT & LOSS STATEMENT — 5-YEAR PROJECTION
B3: All values in ₹. Revenue linked to Revenue Model. Costs linked to Cost sheet. Scenario-driven.
B5: PROFIT & LOSS — INCOME STATEMENT
B6: Particular | C6: Year 1 | D6: Year 2 | E6: Year 3 | F6: Year 4 | G6: Year 5 | H6: 5-Yr Total
B7: REVENUE
B8: Gross Revenue | C8: ='Revenue Model'!C14 -> 11196000 | D8: ='Revenue Model'!D14 -> 11755800 | E8: ='Revenue Model'!E14 -> 12343590 | F8: ='Revenue Model'!F14 -> 12960770 | G8: ='Revenue Model'!G14 -> 13608808 | H8: =SUM(C8:G8) -> 61864967
B9: Less: Vacancy & Discounts (5%) | C9: =C8*0.05 -> 559800 | D9: =D8*0.05 -> 587790 | E9: =E8*0.05 -> 617179.5 | F9: =F8*0.05 -> 648038.48 | G9: =G8*0.05 -> 680440.4 | H9: =SUM(C9:G9) -> 3093248.4
B10: NET REVENUE | C10: =C8-C9 -> 10636200 | D10: =D8-D9 -> 11168010 | E10: =E8-E9 -> 11726410 | F10: =F8-F9 -> 12312731 | G10: =G8-G9 -> 12928368 | H10: =SUM(C10:G10) -> 58771719
B12: DIRECT / VARIABLE COSTS
B13: Variable Cost (₹900/seat × occupied seats × 12 months) | C13: ='Cost sheet'!C43*'Cost sheet'!C49*12 -> 864000 | D13: =C13*(1+Input!C19)^1 -> 907200 | E13: =C13*(1+Input!C19)^2 -> 952560 | F13: =C13*(1+Input!C19)^3 -> 1000188 | G13: =C13*(1+Input!C19)^4 -> 1050197.4 | H13: =SUM(C13:G13) -> 4774145.4
B14: GROSS PROFIT (Net Rev − Variable Cost) | C14: =C10-C13 -> 9772200 | D14: =D10-D13 -> 10260810 | E14: =E10-E13 -> 10773850 | F14: =F10-F13 -> 11312543 | G14: =G10-G13 -> 11878170 | H14: =SUM(C14:G14) -> 53997574
B15: Gross Margin % | C15: =IFERROR(C14/C10,0) -> 0.91876798 | D15: =IFERROR(D14/D10,0) -> 0.91876798 | E15: =IFERROR(E14/E10,0) -> 0.91876798 | F15: =IFERROR(F14/F10,0) -> 0.91876798 | G15: =IFERROR(G14/G10,0) -> 0.91876798
B17: FIXED OPERATING EXPENSES
B18: Rent / Loan EMI | C18: ='Cost sheet'!C20*12 -> 8964639.4 | D18: ='Cost sheet'!C20*12 -> 8964639.4 | E18: ='Cost sheet'!C20*12 -> 8964639.4 | F18: ='Cost sheet'!C20*12 -> 8964639.4 | G18: ='Cost sheet'!C20*12 -> 8964639.4 | H18: =SUM(C18:G18) -> 44823197
B19: Salaries (all staff) | C19: =('Cost sheet'!C21+'Cost sheet'!C22+'Cost sheet'!C23+'Cost sheet'!C24+'Cost sheet'!C25+'Cost sheet'!C26)*12 -> 2388000 | D19: =C19*(1+Input!C19) -> 2507400 | E19: =D19*(1+Input!C19) -> 2632770 | F19: =E19*(1+Input!C19) -> 2764408.5 | G19: =F19*(1+Input!C19) -> 2902628.9 | H19: =SUM(C19:G19) -> 13195207
B20: Internet + Base Electricity | C20: =('Cost sheet'!C27+'Cost sheet'!C28)*12 -> 756000 | D20: =C20*(1+Input!C19) -> 793800 | E20: =D20*(1+Input!C19) -> 833490 | F20: =E20*(1+Input!C19) -> 875164.5 | G20: =F20*(1+Input!C19) -> 918922.73 | H20: =SUM(C20:G20) -> 4177377.2
B21: Maintenance & Repairs | C21: ='Cost sheet'!C29*12 -> 180000 | D21: =C21*(1+Input!C19) -> 189000 | E21: =D21*(1+Input!C19) -> 198450 | F21: =E21*(1+Input!C19) -> 208372.5 | G21: =F21*(1+Input!C19) -> 218791.12 | H21: =SUM(C21:G21) -> 994613.62
B22: Marketing & Advertising | C22: ='Cost sheet'!C30*12 -> 240000 | D22: =C22*(1+Input!C19) -> 252000 | E22: =D22*(1+Input!C19) -> 264600 | F22: =E22*(1+Input!C19) -> 277830 | G22: =F22*(1+Input!C19) -> 291721.5 | H22: =SUM(C22:G22) -> 1326151.5
B23: Admin, Insurance & Misc | C23: =('Cost sheet'!C31+'Cost sheet'!C32+'Cost sheet'!C33)*12 -> 204000 | D23: =C23*(1+Input!C19) -> 214200 | E23: =D23*(1+Input!C19) -> 224910 | F23: =E23*(1+Input!C19) -> 236155.5 | G23: =F23*(1+Input!C19) -> 247963.28 | H23: =SUM(C23:G23) -> 1127228.8
B24: TOTAL FIXED OPERATING EXPENSES | C24: =SUM(C18:C23) -> 12732639 | D24: =SUM(D18:D23) -> 12921039 | E24: =SUM(E18:E23) -> 13118859 | F24: =SUM(F18:F23) -> 13326570 | G24: =SUM(G18:G23) -> 13544667 | H24: =SUM(C24:G24) -> 65643775
B26: EBITDA | C26: =C14-C24 -> -2960439.4 | D26: =D14-D24 -> -2660229.4 | E26: =E14-E24 -> -2345008.9 | F26: =F14-F24 -> -2014027.3 | G26: =G14-G24 -> -1666496.7 | H26: =SUM(C26:G26) -> -11646202
B27: EBITDA Margin % | C27: =IFERROR(C26/C10,0) -> -0.27833619 | D27: =IFERROR(D26/D10,0) -> -0.23820084 | E27: =IFERROR(E26/E10,0) -> -0.1999767 | F27: =IFERROR(F26/F10,0) -> -0.16357276 | G27: =IFERROR(G26/G10,0) -> -0.12890233
B29: DEPRECIATION
B30: Depreciation — Fit-out (SLM, 10%/yr) | C30: ='Cost sheet'!C7*Assumptions!E19 -> 875000 | D30: ='Cost sheet'!C7*Assumptions!E19 -> 875000 | E30: ='Cost sheet'!C7*Assumptions!E19 -> 875000 | F30: ='Cost sheet'!C7*Assumptions!E19 -> 875000 | G30: ='Cost sheet'!C7*Assumptions!E19 -> 875000 | H30: =SUM(C30:G30) -> 4375000
B31: Depreciation — Furniture (WDV, 20%/yr) | C31: ='Cost sheet'!C8*Assumptions!E20*(1-Assumptions!E20)^0 -> 500000 | D31: ='Cost sheet'!C8*Assumptions!E20*(1-Assumptions!E20)^1 -> 400000 | E31: ='Cost sheet'!C8*Assumptions!E20*(1-Assumptions!E20)^2 -> 320000 | F31: ='Cost sheet'!C8*Assumptions!E20*(1-Assumptions!E20)^3 -> 256000 | G31: ='Cost sheet'!C8*Assumptions!E20*(1-Assumptions!E20)^4 -> 204800 | H31: =SUM(C31:G31) -> 1680800
B32: Depreciation — IT (WDV, 33%/yr) | C32: ='Cost sheet'!C9*Assumptions!E21*(1-Assumptions!E21)^0 -> 247500 | D32: ='Cost sheet'!C9*Assumptions!E21*(1-Assumptions!E21)^1 -> 165825 | E32: ='Cost sheet'!C9*Assumptions!E21*(1-Assumptions!E21)^2 -> 111102.75 | F32: ='Cost sheet'!C9*Assumptions!E21*(1-Assumptions!E21)^3 -> 74438.842 | G32: ='Cost sheet'!C9*Assumptions!E21*(1-Assumptions!E21)^4 -> 49874.024 | H32: =SUM(C32:G32) -> 648740.62
B33: TOTAL DEPRECIATION | C33: =SUM(C30:C32) -> 1622500 | D33: =SUM(D30:D32) -> 1440825 | E33: =SUM(E30:E32) -> 1306102.8 | F33: =SUM(F30:F32) -> 1205438.8 | G33: =SUM(G30:G32) -> 1129674 | H33: =SUM(C33:G33) -> 6704540.6
B35: EBIT (EBITDA − Depreciation) | C35: =C26-C33 -> -4582939.4 | D35: =D26-D33 -> -4101054.4 | E35: =E26-E33 -> -3651111.6 | F35: =F26-F33 -> -3219466.2 | G35: =G26-G33 -> -2796170.8 | H35: =SUM(C35:G35) -> -18350742
B36: EBIT Margin % | C36: =IFERROR(C35/C10,0) -> -0.43088127 | D36: =IFERROR(D35/D10,0) -> -0.36721443 | E36: =IFERROR(E35/E10,0) -> -0.31135799 | F36: =IFERROR(F35/F10,0) -> -0.26147458 | G36: =IFERROR(G35/G10,0) -> -0.21628181
B38: INTEREST ON LOAN
B39: Interest Expense (declining on outstanding balance) | C39: ='Cost sheet'!C81 -> 5337000 | D39: =IFERROR('Cost sheet'!C79*Input!C22*(1-((2-1)/Input!C23)),0) -> 4574571.4 | E39: =IFERROR('Cost sheet'!C79*Input!C22*(1-((3-1)/Input!C23)),0) -> 3812142.9 | F39: =IFERROR('Cost sheet'!C79*Input!C22*(1-((4-1)/Input!C23)),0) -> 3049714.3 | G39: =IFERROR('Cost sheet'!C79*Input!C22*(1-((5-1)/Input!C23)),0) -> 2287285.7 | H39: =SUM(C39:G39) -> 19060714
B41: PBT (EBIT − Interest) | C41: =C35-C39 -> -9919939.4 | D41: =D35-D39 -> -8675625.8 | E41: =E35-E39 -> -7463254.5 | F41: =F35-F39 -> -6269180.5 | G41: =G35-G39 -> -5083456.5 | H41: =SUM(C41:G41) -> -37411457
B42: Corporate Tax (25%) | C42: =MAX(0,C41*Input!C21) -> 0 | D42: =MAX(0,D41*Input!C21) -> 0 | E42: =MAX(0,E41*Input!C21) -> 0 | F42: =MAX(0,F41*Input!C21) -> 0 | G42: =MAX(0,G41*Input!C21) -> 0 | H42: =SUM(C42:G42) -> 0
B43: PAT — NET PROFIT / (LOSS) | C43: =C41-C42 -> -9919939.4 | D43: =D41-D42 -> -8675625.8 | E43: =E41-E42 -> -7463254.5 | F43: =F41-F42 -> -6269180.5 | G43: =G41-G42 -> -5083456.5 | H43: =SUM(C43:G43) -> -37411457
B44: Net Margin % | C44: =IFERROR(C43/C10,0) -> -0.93265822 | D44: =IFERROR(D43/D10,0) -> -0.77682826 | E44: =IFERROR(E43/E10,0) -> -0.63644834 | F44: =IFERROR(F43/F10,0) -> -0.50916246 | G44: =IFERROR(G43/G10,0) -> -0.39320173
B45: Retained Earnings (cumulative) | C45: =C43 -> -9919939.4 | D45: =C45+D43 -> -18595565 | E45: =D45+E43 -> -26058820 | F45: =E45+F43 -> -32328000 | G45: =F45+G43 -> -37411457 | H45: =SUM(C43:G43) -> -37411457
B47: PROFIT CASES ANALYSIS (YEAR 1 BASE)
B48: Case | C48: Target PAT | D48: Required Annual Revenue | E48: Required Occupancy % | F48: Required Price/Seat | G48: Achievable?
B49: Case 1 — Positive Contribution Margin | C49: Contribution > 0 | D49: ='Cost sheet'!C43*'Cost sheet'!C49*12 -> 864000 | E49: =IFERROR('Cost sheet'!C43*Input!C10*12/('Revenue Model'!C14/Input!C13),0) -> 0.077170418 | F49: ='Cost sheet'!C43 -> 900 | G49: =IF(Input!C14>'Cost sheet'!C43,"✓ Yes — Contribution Positive","✗ Price below var cost") -> ✓ Yes — Contribution Positive
...

Sheet Cash Budget
B1: Navigation Tab
B2: CASH BUDGET — YEAR 1 MONTHLY + YEARS 2–5 ANNUAL
B3: Year 1: month-by-month cash flows. Years 2–5: annual summary. All linked to Input, Costs & P&L.
B5: YEAR 1 — MONTHLY CASH BUDGET
B6: Item | C6: Jan | D6: Feb | E6: Mar | F6: Apr | G6: May | H6: Jun | I6: Jul | J6: Aug | K6: Sep | L6: Oct | M6: Nov | N6: Dec | O6: Yr 1 Total
B7: CASH INFLOWS
B8: Subscription Revenue (monthly) | C8: =Revenue!F21 -> 933000 | D8: =Revenue!F21 -> 933000 | E8: =Revenue!F21 -> 933000 | F8: =Revenue!F21 -> 933000 | G8: =Revenue!F21 -> 933000 | H8: =Revenue!F21 -> 933000 | I8: =Revenue!F21 -> 933000 | J8: =Revenue!F21 -> 933000 | K8: =Revenue!F21 -> 933000 | L8: =Revenue!F21 -> 933000 | M8: =Revenue!F21 -> 933000 | N8: =Revenue!F21 -> 933000 | O8: =SUM(C8:N8) -> 11196000
B9: Advance Receipts (2-month advance — Month 1 only) | C9: =Revenue!F21*Input!C25 -> 1866000 | D9: =0 -> 0 | E9: =0 -> 0 | F9: =0 -> 0 | G9: =0 -> 0 | H9: =0 -> 0 | I9: =0 -> 0 | J9: =0 -> 0 | K9: =0 -> 0 | ... N9: =0 -> 0 | O9: =SUM(C9:N9) -> 1866000
B10: Events & Workation (cash receipts) | C10: =Revenue!F19+Revenue!F20 -> 156000 | D10: =Revenue!F19+Revenue!F20 -> 156000 | E10: =Revenue!F19+Revenue!F20 -> 156000 | F10: =Revenue!F19+Revenue!F20 -> 156000 | G10: =Revenue!F19+Revenue!F20 -> 156000 | H10: =Revenue!F19+Revenue!F20 -> 156000 | I10: =Revenue!F19+Revenue!F20 -> 156000 | J10: =Revenue!F19+Revenue!F20 -> 156000 | K10: =Revenue!F19+Revenue!F20 -> 156000 | L10: =Revenue!F19+Revenue!F20 -> 156000 | M10: =Revenue!F19+Revenue!F20 -> 156000 | N10: =Revenue!F19+Revenue!F20 -> 156000 | O10: =SUM(C10:N10) -> 1872000
B11: TOTAL CASH INFLOWS | C11: =SUM(C8:C10) -> 2955000 | D11: =SUM(D8:D10) -> 1089000 | E11: =SUM(E8:E10) -> 1089000 | F11: =SUM(F8:F10) -> 1089000 | G11: =SUM(G8:G10) -> 1089000 | H11: =SUM(H8:H10) -> 1089000 | I11: =SUM(I8:I10) -> 1089000 | J11: =SUM(J8:J10) -> 1089000 | ... N11: =SUM(N8:N10) -> 1089000 | O11: =SUM(C11:N11) -> 14934000
B13: CASH OUTFLOWS
B14: Rent / EMI (monthly) | C14: ='Cost sheet'!C20 -> 747053.28 | D14: ='Cost sheet'!C20 -> 747053.28 | E14: ='Cost sheet'!C20 -> 747053.28 | F14: ='Cost sheet'!C20 -> 747053.28 | G14: ='Cost sheet'!C20 -> 747053.28 | H14: ='Cost sheet'!C20 -> 747053.28 | I14: ='Cost sheet'!C20 -> 747053.28 | J14: ='Cost sheet'!C20 -> 747053.28 | K14: ='Cost sheet'!C20 -> 747053.28 | L14: ='Cost sheet'!C20 -> 747053.28 | M14: ='Cost sheet'!C20 -> 747053.28 | N14: ='Cost sheet'!C20 -> 747053.28 | O14: =SUM(C14:N14) -> 8964639.4
B15: Salaries (all staff) | C15: ='Cost sheet'!C21+'Cost sheet'!C22+'Cost sheet'!C23+'Cost sheet'!C24+'Cost sheet'!C25+'Cost sheet'!C26 -> 199000 | D15: ='Cost sheet'!C21+'Cost sheet'!C22+'Cost sheet'!C23+'Cost sheet'!C24+'Cost sheet'!C25+'Cost sheet'!C26 -> 199000 | E15: ='Cost sheet'!C21+'Cost sheet'!C22+'Cost sheet'!C23+'Cost sheet'!C24+'Cost sheet'!C25+'Cost sheet'!C26 -> 199000 | F15: ='Cost sheet'!C21+'Cost sheet'!C22+'Cost sheet'!C23+'Cost sheet'!C24+'Cost sheet'!C25+'Cost sheet'!C26 -> 199000 | G15: ='Cost sheet'!C21+'Cost sheet'!C22+'Cost sheet'!C23+'Cost sheet'!C24+'Cost sheet'!C25+'Cost sheet'!C26 -> 199000 | H15: ='Cost sheet'!C21+'Cost sheet'!C22+'Cost sheet'!C23+'Cost sheet'!C24+'Cost sheet'!C25+'Cost sheet'!C26 -> 199000 | I15: ='Cost sheet'!C21+'Cost sheet'!C22+'Cost sheet'!C23+'Cost sheet'!C24+'Cost sheet'!C25+'Cost sheet'!C26 -> 199000 | J15: ='Cost sheet'!C21+'Cost sheet'!C22+'Cost sheet'!C23+'Cost sheet'!C24+'Cost sheet'!C25+'Cost sheet'!C26 -> 199000 | K15: ='Cost sheet'!C21+'Cost sheet'!C22+'Cost sheet'!C23+'Cost sheet'!C24+'Cost sheet'!C25+'Cost sheet'!C26 -> 199000 | L15: ='Cost sheet'!C21+'Cost sheet'!C22+'Cost sheet'!C23+'Cost sheet'!C24+'Cost sheet'!C25+'Cost sheet'!C26 -> 199000 | M15: ='Cost sheet'!C21+'Cost sheet'!C22+'Cost sheet'!C23+'Cost sheet'!C24+'Cost sheet'!C25+'Cost sheet'!C26 -> 199000 | N15: ='Cost sheet'!C21+'Cost sheet'!C22+'Cost sheet'!C23+'Cost sheet'!C24+'Cost sheet'!C25+'Cost sheet'!C26 -> 199000 | O15: =SUM(C15:N15) -> 2388000
B16: Utilities, Internet & Fixed Overheads | C16: ='Cost sheet'!C27+'Cost sheet'!C28+'Cost sheet'!C29+'Cost sheet'!C30+'Cost sheet'!C31+'Cost sheet'!C32+'Cost sheet'!C33 -> 115000 | D16: ='Cost sheet'!C27+'Cost sheet'!C28+'Cost sheet'!C29+'Cost sheet'!C30+'Cost sheet'!C31+'Cost sheet'!C32+'Cost sheet'!C33 -> 115000 | E16: ='Cost sheet'!C27+'Cost sheet'!C28+'Cost sheet'!C29+'Cost sheet'!C30+'Cost sheet'!C31+'Cost sheet'!C32+'Cost sheet'!C33 -> 115000 | F16: ='Cost sheet'!C27+'Cost sheet'!C28+'Cost sheet'!C29+'Cost sheet'!C30+'Cost sheet'!C31+'Cost sheet'!C32+'Cost sheet'!C33 -> 115000 | G16: ='Cost sheet'!C27+'Cost sheet'!C28+'Cost sheet'!C29+'Cost sheet'!C30+'Cost sheet'!C31+'Cost sheet'!C32+'Cost sheet'!C33 -> 115000 | H16: ='Cost sheet'!C27+'Cost sheet'!C28+'Cost sheet'!C29+'Cost sheet'!C30+'Cost sheet'!C31+'Cost sheet'!C32+'Cost sheet'!C33 -> 115000 | I16: ='Cost sheet'!C27+'Cost sheet'!C28+'Cost sheet'!C29+'Cost sheet'!C30+'Cost sheet'!C31+'Cost sheet'!C32+'Cost sheet'!C33 -> 115000 | J16: ='Cost sheet'!C27+'Cost sheet'!C28+'Cost sheet'!C29+'Cost sheet'!C30+'Cost sheet'!C31+'Cost sheet'!C32+'Cost sheet'!C33 -> 115000 | K16: ='Cost sheet'!C27+'Cost sheet'!C28+'Cost sheet'!C29+'Cost sheet'!C30+'Cost sheet'!C31+'Cost sheet'!C32+'Cost sheet'!C33 -> 115000 | L16: ='Cost sheet'!C27+'Cost sheet'!C28+'Cost sheet'!C29+'Cost sheet'!C30+'Cost sheet'!C31+'Cost sheet'!C32+'Cost sheet'!C33 -> 115000 | M16: ='Cost sheet'!C27+'Cost sheet'!C28+'Cost sheet'!C29+'Cost sheet'!C30+'Cost sheet'!C31+'Cost sheet'!C32+'Cost sheet'!C33 -> 115000 | N16: ='Cost sheet'!C27+'Cost sheet'!C28+'Cost sheet'!C29+'Cost sheet'!C30+'Cost sheet'!C31+'Cost sheet'!C32+'Cost sheet'!C33 -> 115000 | O16: =SUM(C16:N16) -> 1380000
B17: Variable Costs (occupied seats × ₹900) | C17: ='Cost sheet'!C49*'Cost sheet'!C43 -> 72000 | D17: ='Cost sheet'!C49*'Cost sheet'!C43 -> 72000 | E17: ='Cost sheet'!C49*'Cost sheet'!C43 -> 72000 | F17: ='Cost sheet'!C49*'Cost sheet'!C43 -> 72000 | G17: ='Cost sheet'!C49*'Cost sheet'!C43 -> 72000 | H17: ='Cost sheet'!C49*'Cost sheet'!C43 -> 72000 | I17: ='Cost sheet'!C49*'Cost sheet'!C43 -> 72000 | J17: ='Cost sheet'!C49*'Cost sheet'!C43 -> 72000 | K17: ='Cost sheet'!C49*'Cost sheet'!C43 -> 72000 | L17: ='Cost sheet'!C49*'Cost sheet'!C43 -> 72000 | M17: ='Cost sheet'!C49*'Cost sheet'!C43 -> 72000 | N17: ='Cost sheet'!C49*'Cost sheet'!C43 -> 72000 | O17: =SUM(C17:N17) -> 864000
B18: CAPEX Payment (Month 1 only — equity portion) | C18: ='Cost sheet'!C84 -> 35580000 | D18: =0 -> 0 | E18: =0 -> 0 | F18: =0 -> 0 | G18: =0 -> 0 | H18: =0 -> 0 | I18: =0 -> 0 | J18: =0 -> 0 | K18: =0 -> 0 | ... N18: =0 -> 0 | O18: =SUM(C18:N18) -> 35580000
B19: TOTAL CASH OUTFLOWS | C19: =SUM(C14:C18) -> 36713053 | D19: =SUM(D14:D18) -> 1133053.3 | E19: =SUM(E14:E18) -> 1133053.3 | F19: =SUM(F14:F18) -> 1133053.3 | G19: =SUM(G14:G18) -> 1133053.3 | H19: =SUM(H14:H18) -> 1133053.3 | I19: =SUM(I14:I18) -> 1133053.3 | J19: =SUM(J14:J18) -> 1133053.3 | ... N19: =SUM(N14:N18) -> 1133053.3 | O19: =SUM(C19:N19) -> 49176639
B21: NET CASH FLOW & BALANCES
B22: NET CASH FLOW (Inflows − Outflows) | C22: =C11-C19 -> -33758053 | D22: =D11-D19 -> -44053.281 | E22: =E11-E19 -> -44053.281 | F22: =F11-F19 -> -44053.281 | G22: =G11-G19 -> -44053.281 | H22: =H11-H19 -> -44053.281 | I22: =I11-I19 -> -44053.281 | J22: =J11-J19 -> -44053.281 | ... N22: =N11-N19 -> -44053.281 | O22: =SUM(C22:N22) -> -34242639
B23: Opening Cash Balance | C23: ='Cost sheet'!C79 -> 53370000 | D23: =C24 -> 19611947 | E23: =D24 -> 19567893 | F23: =E24 -> 19523840 | G23: =F24 -> 19479787 | H23: =G24 -> 19435734 | I23: =H24 -> 19391680 | J23: =I24 -> 19347627 | K23: =J24 -> 19303574 | ... N23: =M24 -> 19171414
B24: CLOSING CASH BALANCE | C24: =C23+C22 -> 19611947 | D24: =D23+D22 -> 19567893 | E24: =E23+E22 -> 19523840 | F24: =F23+F22 -> 19479787 | G24: =G23+G22 -> 19435734 | H24: =H23+H22 -> 19391680 | I24: =I23+I22 -> 19347627 | J24: =J23+J22 -> 19303574 | ... N24: =N23+N22 -> 19127361 | O24: =N24 -> 19127361
B26: YEARS 2–5 ANNUAL CASH SUMMARY
B27: Item | C27: Year 2 | D27: Year 3 | E27: Year 4 | F27: Year 5 | G27: 4-Year Total
B28: Total Cash Inflows (Revenue) | C28: ='P&L'!C10 -> 10636200 | D28: ='P&L'!D10 -> 11168010 | E28: ='P&L'!E10 -> 11726410 | F28: ='P&L'!F10 -> 12312731 | G28: =SUM(C28:F28) -> 45843352
B29: Total Cash Outflows (Operating Costs) | C29: ='P&L'!C13+'P&L'!C24 -> 13596639 | D29: ='P&L'!D13+'P&L'!D24 -> 13828239 | E29: ='P&L'!E13+'P&L'!E24 -> 14071419 | F29: ='P&L'!F13+'P&L'!F24 -> 14326758 | G29: =SUM(C29:F29) -> 55823056
B30: Net Cash Flow (before financing) | C30: =C28-C29 -> -2960439.4 | D30: =D28-D29 -> -2660229.4 | E30: =E28-E29 -> -2345008.9 | F30: =F28-F29 -> -2014027.3 | G30: =SUM(C30:F30) -> -9979705
B31: Opening Cash Balance | C31: =N24 -> 19127361 | D31: =C32 -> 16166921 | E31: =D32 -> 13506692 | F31: =E32 -> 11161683
B32: CLOSING CASH BALANCE | C32: =C31+C30 -> 16166921 | D32: =D31+D30 -> 13506692 | E32: =E31+E30 -> 11161683 | F32: =F31+F30 -> 9147655.7 | G32: =F32 -> 9147655.7
B34: Note: Yr2-5 net CF = Revenue − Operating Costs (EBITDA proxy). Loan repayments excluded here; see Costs sheet Part F for full debt schedule.
B36: CASH FLOW KPIs
B37: Min Monthly Closing Balance (Yr 1) | C37: =MIN(C24:N24) -> 19127361
B38: Max Monthly Closing Balance (Yr 1) | C38: =MAX(C24:N24) -> 19611947
B39: Months with Negative Closing Balance | C39: =COUNTIF(C24:N24,"<0") -> 0
B40: Avg Monthly Net Cash Flow (Yr 1) | C40: =AVERAGE(C22:N22) -> -2853553.3
B41: Yr 1 Total Cash Inflow | C41: =O11 -> 14934000
B42: Yr 1 Total Cash Outflow | C42: =O19 -> 49176639
B43: Yr 1 Net Cash Flow | C43: =O22 -> -34242639
B44: Closing Cash Balance Yr 5 | C44: =F32 -> 9147655.7

Sheet Working Capital
B1: Navigation Tab
B2: WORKING CAPITAL SCHEDULE — 5-YEAR PROJECTION
B3: Receivables, Payables, Advances & Cash Buffer. All linked to P&L and Input sheets.
B5: WORKING CAPITAL COMPONENTS (₹)
B6: Working Capital Item | C6: Year 1 | D6: Year 2 | E6: Year 3 | F6: Year 4 | G6: Year 5 | H6: Notes
B7: CURRENT ASSETS
B8: Trade Receivables (30-day debtors) | C8: ='P&L'!C10/12 -> 886350 | D8: ='P&L'!D10/12 -> 930667.5 | E8: ='P&L'!E10/12 -> 977200.88 | F8: ='P&L'!F10/12 -> 1026060.9 | G8: ='P&L'!G10/12 -> 1077364 | H8: Customers paying within 30 days
B9: Advance Receipts Collected (2-month) | C9: ='P&L'!C10/12*Input!C25 -> 1772700 | D9: ='P&L'!D10/12*Input!C25 -> 1861335 | E9: ='P&L'!E10/12*Input!C25 -> 1954401.8 | F9: ='P&L'!F10/12*Input!C25 -> 2052121.8 | G9: ='P&L'!G10/12*Input!C25 -> 2154727.9 | H9: Advance desk fees collected per Input!C25 months
B10: Cash & Bank Balance (closing) | C10: ='Cash Budget'!N24 -> 19127361 | D10: ='Cash Budget'!C32 -> 16166921 | E10: ='Cash Budget'!D32 -> 13506692 | F10: ='Cash Budget'!E32 -> 11161683 | G10: ='Cash Budget'!F32 -> 9147655.7 | H10: Linked from CashBudget closing balance
B11: Prepaid Expenses (1-month advance costs) | C11: ='Cost sheet'!C34 -> 1061053.3 | D11: =C11*(1+Input!C19) -> 1114105.9 | E11: =D11*(1+Input!C19) -> 1169811.2 | F11: =E11*(1+Input!C19) -> 1228301.8 | G11: =F11*(1+Input!C19) -> 1289716.9 | H11: Insurance, rent advance etc.
B12: TOTAL CURRENT ASSETS | C12: =SUM(C8:C11) -> 22847464 | D12: =SUM(D8:D11) -> 20073030 | E12: =SUM(E8:E11) -> 17608106 | F12: =SUM(F8:F11) -> 15468168 | G12: =SUM(G8:G11) -> 13669464 | H12: Sum of all current assets
B14: CURRENT LIABILITIES
B15: Trade Payables (30-day creditor terms) | C15: ='Cost sheet'!C34+'Cost sheet'!C51 -> 1133053.3 | D15: =('P&L'!D13+'P&L'!D24)/12 -> 1152353.3 | E15: =('P&L'!E13+'P&L'!E24)/12 -> 1172618.3 | F15: =('P&L'!F13+'P&L'!F24)/12 -> 1193896.5 | G15: =('P&L'!G13+'P&L'!G24)/12 -> 1216238.7 | H15: Vendors, utilities, consumables on 30-day terms
B16: Advance from Customers (refundable) | C16: =C9 -> 1772700 | D16: =D9 -> 1861335 | E16: =E9 -> 1954401.8 | F16: =F9 -> 2052121.8 | G16: =G9 -> 2154727.9 | H16: Mirrors advance receipts current asset (net = 0)
B17: Salaries Payable (current month accrual) | C17: =('Cost sheet'!C21+'Cost sheet'!C22+'Cost sheet'!C23+'Cost sheet'!C24+'Cost sheet'!C25+'Cost sheet'!C26) -> 199000 | D17: =C17*(1+Input!C19) -> 208950 | E17: =D17*(1+Input!C19) -> 219397.5 | F17: =E17*(1+Input!C19) -> 230367.38 | G17: =F17*(1+Input!C19) -> 241885.74 | H17: Salaries accrued but unpaid at month-end
B18: Loan — Current Portion (annual principal due) | C18: ='Cost sheet'!C82 -> 3627639.4 | D18: ='Cost sheet'!C82*(1+0.02) -> 3700192.2 | E18: ='Cost sheet'!C82*(1+0.04) -> 3772744.9 | F18: ='Cost sheet'!C82*(1+0.06) -> 3845297.7 | G18: ='Cost sheet'!C82*(1+0.08) -> 3917850.5 | H18: Current portion of long-term loan
B19: TOTAL CURRENT LIABILITIES | C19: =SUM(C15:C18) -> 6732392.7 | D19: =SUM(D15:D18) -> 6922830.4 | E19: =SUM(E15:E18) -> 7119162.5 | F19: =SUM(F15:F18) -> 7321683.5 | G19: =SUM(G15:G18) -> 7530702.9 | H19: Sum of all current liabilities
B21: NET WORKING CAPITAL & RATIOS
B22: NET WORKING CAPITAL (CA − CL) | C22: =C12-C19 -> 16115071 | D22: =D12-D19 -> 13150199 | E22: =E12-E19 -> 10488943 | F22: =F12-F19 -> 8146484.1 | G22: =G12-G19 -> 6138761.6 | H22: Positive = healthy; Negative = short-term stress
B23: Current Ratio (CA ÷ CL) | C23: =IFERROR(C12/C19,0) -> 3.3936618 | D23: =IFERROR(D12/D19,0) -> 2.8995409 | E23: =IFERROR(E12/E19,0) -> 2.4733395 | F23: =IFERROR(F12/F19,0) -> 2.1126518 | G23: =IFERROR(G12/G19,0) -> 1.8151645 | H23: Current assets ÷ current liabilities
B24: Quick Ratio ((CA − Prepaid) ÷ CL) | C24: =IFERROR((C12-C11)/C19,0) -> 3.2360576 | D24: =IFERROR((D12-D11)/D19,0) -> 2.7386087 | E24: =IFERROR((E12-E11)/E19,0) -> 2.3090208 | F24: =IFERROR((F12-F11)/F19,0) -> 1.9448896 | G24: =IFERROR((G12-G11)/G19,0) -> 1.6439033 | H24: Liquid assets ÷ current liabilities
B25: Cash Buffer (months of fixed costs) | C25: =IFERROR(C10/'Cost sheet'!C34,0) -> 18.026767 | D25: =IFERROR(D10/('P&L'!D24/12),0) -> 15.014508 | E25: =IFERROR(E10/('P&L'!E24/12),0) -> 12.354756 | F25: =IFERROR(F10/('P&L'!F24/12),0) -> 10.050613 | G25: =IFERROR(G10/('P&L'!G24/12),0) -> 8.1044346 | H25: Cash balance ÷ monthly fixed costs
B26: Working Capital Days | C26: =IFERROR(C22/('P&L'!C10/365),0) -> 553.01715 | D26: =IFERROR(D22/('P&L'!D10/365),0) -> 429.78317 | E26: =IFERROR(E22/('P&L'!E10/365),0) -> 326.4822 | F26: =IFERROR(F22/('P&L'!F10/365),0) -> 241.4953 | G26: =IFERROR(G22/('P&L'!G10/365),0) -> 173.31252 | H26: Days of revenue tied up in working capital
B28: ℹ High WC Days & Cash Buffer reflect loan proceeds (₹14.3 Cr) held in cash. Operational WC excludes loan capital. Switch to Rent scenario for leaner cash position.
B30: RECEIVABLES & PAYABLES DETAIL
B31: Metric | C31: Year 1 | D31: Year 2 | E31: Year 3 | F31: Year 4 | G31: Year 5 | H31: Notes
B32: Debtor Days (Receivable Collection Period) | C32: =IFERROR(C8/('P&L'!C10/365),0) -> 30.416667 | D32: =IFERROR(D8/('P&L'!D10/365),0) -> 30.416667 | E32: =IFERROR(E8/('P&L'!E10/365),0) -> 30.416667 | F32: =IFERROR(F8/('P&L'!F10/365),0) -> 30.416667 | G32: =IFERROR(G8/('P&L'!G10/365),0) -> 30.416667 | H32: Target: ≤ 30 days
B33: Creditor Days (Payable Payment Period) | C33: =IFERROR(C15/('P&L'!C13+'P&L'!C24)*365,0) -> 30.416667 | D33: =IFERROR(D15/('P&L'!D13+'P&L'!D24)*365,0) -> 30.416667 | E33: =IFERROR(E15/('P&L'!E13+'P&L'!E24)*365,0) -> 30.416667 | F33: =IFERROR(F15/('P&L'!F13+'P&L'!F24)*365,0) -> 30.416667 | G33: =IFERROR(G15/('P&L'!G13+'P&L'!G24)*365,0) -> 30.416667 | H33: Target: ≤ 30 days
B34: Advance Collection (months) | C34: =Input!C25 -> 2 | D34: =Input!C25 -> 2 | E34: =Input!C25 -> 2 | F34: =Input!C25 -> 2 | G34: =Input!C25 -> 2 | H34: From Input!C25
B35: Monthly Revenue Cycle (days) | C35: =30 -> 30 | D35: =30 -> 30 | E35: =30 -> 30 | F35: =30 -> 30 | G35: =30 -> 30 | H35: Monthly subscription model = 30-day cycle

Sheet Standard Cost
B1: Navigation Tab
B2: STANDARD COSTING — COST PER DESK & PER USER
B3: Standard costs derived from Input & Assumptions. All formulas linked .
B5: A. STANDARD CAPACITY PARAMETERS
B6: Parameter | C6: Standard Value | D6: Unit | E6: Source / Notes
B7: Total Installed Capacity (seats) | C7: =Input!C10 -> 100 | D7: seats | E7: Input!C10
B8: Standard Occupancy Rate | C8: =Input!C13 -> 0.8 | D8: % | E8: Input!C13
B9: Standard Occupied Seats | C9: =Input!C10*Input!C13 -> 80 | D9: seats | E9: Total × Occupancy
B10: Total Floor Area | C10: =Input!C12 -> 5000 | D10: sq ft | E10: Input!C12
B11: Area per Seat | C11: =Input!C12/Input!C10 -> 50 | D11: sq ft | E11: Total Area / Seats
B12: Standard Revenue per Seat (month) | C12: =Input!C14 -> 7500 | D12: ₹/seat | E12: Input!C14
B13: Operating Days per Year | C13: 365 | D13: days | E13: Calendar assumption
B14: Operating Hours per Day | C14: 10 | D14: hours | E14: 9 AM – 7 PM
B16: B. STANDARD FIXED COST PER SEAT (MONTHLY)
B17: Fixed Cost Component | C17: Monthly Total (₹) | D17: Per Total Seat (₹) | E17: Per Occupied Seat (₹) | F17: % of Total Fixed
B18: Rent / EMI | C18: ='Cost sheet'!C20 -> 747053.28 | D18: =IFERROR(C18/Input!C10,0) -> 7470.5328 | E18: =IFERROR(C18/(Input!C10*Input!C13),0) -> 9338.166 | F18: =IFERROR(C18/'Cost sheet'!C34,0) -> 0.70406764
B19: Salaries — all staff | C19: ='Cost sheet'!C21+'Cost sheet'!C22+'Cost sheet'!C23+'Cost sheet'!C24+'Cost sheet'!C25+'Cost sheet'!C26 -> 199000 | D19: =IFERROR(C19/Input!C10,0) -> 1990 | E19: =IFERROR(C19/(Input!C10*Input!C13),0) -> 2487.5 | F19: =IFERROR(C19/'Cost sheet'!C34,0) -> 0.18754949
B20: Internet | C20: ='Cost sheet'!C27 -> 18000 | D20: =IFERROR(C20/Input!C10,0) -> 180 | E20: =IFERROR(C20/(Input!C10*Input!C13),0) -> 225 | F20: =IFERROR(C20/'Cost sheet'!C34,0) -> 0.016964275
B21: Electricity (base) | C21: ='Cost sheet'!C28 -> 45000 | D21: =IFERROR(C21/Input!C10,0) -> 450 | E21: =IFERROR(C21/(Input!C10*Input!C13),0) -> 562.5 | F21: =IFERROR(C21/'Cost sheet'!C34,0) -> 0.042410688
B22: Maintenance | C22: ='Cost sheet'!C29 -> 15000 | D22: =IFERROR(C22/Input!C10,0) -> 150 | E22: =IFERROR(C22/(Input!C10*Input!C13),0) -> 187.5 | F22: =IFERROR(C22/'Cost sheet'!C34,0) -> 0.014136896
B23: Marketing | C23: ='Cost sheet'!C30 -> 20000 | D23: =IFERROR(C23/Input!C10,0) -> 200 | E23: =IFERROR(C23/(Input!C10*Input!C13),0) -> 250 | F23: =IFERROR(C23/'Cost sheet'!C34,0) -> 0.018849195
B24: Admin, Insurance & Misc | C24: ='Cost sheet'!C31+'Cost sheet'!C32+'Cost sheet'!C33 -> 17000 | D24: =IFERROR(C24/Input!C10,0) -> 170 | E24: =IFERROR(C24/(Input!C10*Input!C13),0) -> 212.5 | F24: =IFERROR(C24/'Cost sheet'!C34,0) -> 0.016021816
B25: TOTAL FIXED COST | C25: ='Cost sheet'!C34 -> 1061053.3 | D25: =IFERROR('Cost sheet'!C34/Input!C10,0) -> 10610.533 | E25: =IFERROR('Cost sheet'!C34/(Input!C10*Input!C13),0) -> 13263.166 | F25: =100% -> 1
B27: C. STANDARD VARIABLE COST PER SEAT (MONTHLY)
B28: Variable Cost Component | C28: Per Seat (₹) | D28: Annual per Seat (₹)
B29: Electricity (usage) | C29: =Assumptions!E43 -> 350 | D29: =C29*12 -> 4200
B30: Pantry & Beverages | C30: =Assumptions!E44 -> 200 | D30: =C30*12 -> 2400
B31: Cleaning (incremental) | C31: =Assumptions!E45 -> 150 | D31: =C31*12 -> 1800
B32: Internet (bandwidth) | C32: =Assumptions!E46 -> 120 | D32: =C32*12 -> 1440
B33: Stationery & Misc | C33: =Assumptions!E47 -> 80 | D33: =C33*12 -> 960
B34: TOTAL VARIABLE COST / SEAT | C34: ='Cost sheet'!C43 -> 900 | D34: ='Cost sheet'!C43*12 -> 10800
B36: D. STANDARD COST CARD — PER SEAT PER MONTH
B37: Cost Element | C37: Per Seat / Month (₹) | D37: Per Seat / Year (₹) | E37: % of Total Cost
B38: Variable Cost per Seat | C38: ='Cost sheet'!C43 -> 900 | D38: ='Cost sheet'!C43*12 -> 10800 | E38: =IFERROR(C38/(C38+C39+C40+C41),0) -> 0.042031239
B39: Fixed Cost per Occupied Seat | C39: =IFERROR('Cost sheet'!C34/(Input!C10*Input!C13),0) -> 13263.166 | D39: =IFERROR('Cost sheet'!C34/(Input!C10*Input!C13)*12,0) -> 159157.99 | E39: =IFERROR(C39/(C38+C39+C40+C41),0) -> 0.61940811
B40: Depreciation per Occupied Seat (monthly) | C40: =IFERROR('Cost sheet'!C63/(Input!C10*Input!C13),0) -> 1690.1042 | D40: =IFERROR('Cost sheet'!C63/(Input!C10*Input!C13)*12,0) -> 20281.25 | E40: =IFERROR(C40/(C38+C39+C40+C41),0) -> 0.078930191
B41: Interest per Occupied Seat (monthly) | C41: =IFERROR('Cost sheet'!C66/(Input!C10*Input!C13),0) -> 5559.375 | D41: =IFERROR('Cost sheet'!C66/(Input!C10*Input!C13)*12,0) -> 66712.5 | E41: =IFERROR(C41/(C38+C39+C40+C41),0) -> 0.25963046
B42: TOTAL STANDARD COST PER SEAT | C42: =SUM(C38:C41) -> 21412.645 | D42: =SUM(D38:D41) -> 256951.74 | E42: =100% -> 1
B44: E. REVENUE vs STANDARD COST — VARIANCE ANALYSIS
B45: KPI | C45: Value (₹) | D45: Unit | E45: Interpretation
...

Sheet Flexible Budget
B1: Navigation Tab
B2: FLEXIBLE BUDGET — 40% / 60% / 80% OCCUPANCY
B3: Full P&L rebuilt for 3 occupancy levels. Fixed costs stay constant; variable costs scale with seats.
B5: FLEXIBLE BUDGET STATEMENT (MONTHLY)
B6: Budget Line Item | C6: 40% Occupancy | D6: 60% Occupancy | E6: 80% Occupancy | F6: Active Scenario | G6: Var: 40% vs 60% | H6: Var: 60% vs 80%
B7: REVENUE
B8: Hot Desk Revenue | C8: =ROUND(Input!C10*0.4*0.45,0)*Input!C14 -> 135000 | D8: =ROUND(Input!C10*0.6*0.45,0)*Input!C14 -> 202500 | E8: =ROUND(Input!C10*0.8*0.45,0)*Input!C14 -> 270000 | F8: =IF(Input!C13=0.4,C8,IF(Input!C13=0.6,D8,E8)) -> 270000 | G8: =D8-C8 -> 67500 | H8: =E8-D8 -> 67500
